<sdf version="1.9">
<model name="boden_description" canonical_link="main_plate_link">
  <joint name="Zed2i_link_joint" type="fixed">
    <pose relative_to="electronics_link">-0.08420 0.00894 0.08299 1.57080 0.00000 -1.57080</pose>
    <parent>electronics_link</parent>
    <child>Zed2i_link</child>
    <axis/>
  </joint>
  <joint name="base_link_joint" type="fixed">
    <pose relative_to="main_plate_link">0.00000 0.00000 -0.23899 0.00000 0.00000 0.00000</pose>
    <parent>main_plate_link</parent>
    <child>base_link</child>
    <axis/>
  </joint>
  <joint name="battery_link_joint" type="fixed">
    <pose relative_to="main_plate_link">0.05208 0.00000 0.05627 0.00000 0.00000 0.00000</pose>
    <parent>main_plate_link</parent>
    <child>battery_link</child>
    <axis/>
  </joint>
  <joint name="electronics_link_joint" type="fixed">
    <pose relative_to="main_plate_link">-0.08592 -0.00513 0.10698 0.00000 0.00000 0.00000</pose>
    <parent>main_plate_link</parent>
    <child>electronics_link</child>
    <axis/>
  </joint>
  <joint name="left_wheel_1_link_joint" type="continuous">
    <pose relative_to="suspension_left_main_link">-0.29512 -0.20932 0.09071 0.00000 -0.00000 2.05076</pose>
    <parent>suspension_left_main_link</parent>
    <child>left_wheel_1_link</child>
    <axis>
      <limit>
        <lower>0.00000</lower>
        <upper>0.00000</upper>
        <effort>1000.00000</effort>
        <velocity>10.00000</velocity>
      </limit>
      <xyz>0.00000 0.00000 1.00000</xyz>
    </axis>
  </joint>
  <joint name="left_wheel_2_link_joint" type="continuous">
    <pose relative_to="suspension_left_sub_link">-0.12032 -0.18908 0.02638 0.00000 0.00000 2.34661</pose>
    <parent>suspension_left_sub_link</parent>
    <child>left_wheel_2_link</child>
    <axis>
      <limit>
        <lower>0.00000</lower>
        <upper>0.00000</upper>
        <effort>1000.00000</effort>
        <velocity>10.00000</velocity>
      </limit>
      <xyz>0.00000 0.00000 1.00000</xyz>
    </axis>
  </joint>
  <joint name="left_wheel_3_link_joint" type="continuous">
    <pose relative_to="suspension_left_sub_link">0.17866 -0.06537 0.02638 0.00000 0.00000 0.26966</pose>
    <parent>suspension_left_sub_link</parent>
    <child>left_wheel_3_link</child>
    <axis>
      <limit>
        <lower>0.00000</lower>
        <upper>0.00000</upper>
        <effort>1000.00000</effort>
        <velocity>10.00000</velocity>
      </limit>
      <xyz>0.00000 0.00000 1.00000</xyz>
    </axis>
  </joint>
  <joint name="right_wheel_1_link_joint" type="continuous">
    <pose relative_to="suspension_right_sub_link">0.12032 -0.18908 0.02638 -0.00000 0.00000 -2.34661</pose>
    <parent>suspension_right_sub_link</parent>
    <child>right_wheel_1_link</child>
    <axis>
      <limit>
        <lower>0.00000</lower>
        <upper>0.00000</upper>
        <effort>1000.00000</effort>
        <velocity>10.00000</velocity>
      </limit>
      <xyz>0.00000 0.00000 1.00000</xyz>
    </axis>
  </joint>
  <joint name="right_wheel_2_link_joint" type="continuous">
    <pose relative_to="suspension_right_sub_link">-0.17866 -0.06537 0.02638 0.00000 -0.00000 2.19125</pose>
    <parent>suspension_right_sub_link</parent>
    <child>right_wheel_2_link</child>
    <axis>
      <limit>
        <lower>0.00000</lower>
        <upper>0.00000</upper>
        <effort>1000.00000</effort>
        <velocity>10.00000</velocity>
      </limit>
      <xyz>0.00000 0.00000 1.00000</xyz>
    </axis>
  </joint>
  <joint name="right_wheel_3_joint" type="continuous">
    <pose relative_to="suspension_right_main_link">0.29512 -0.20932 0.09071 -0.00000 0.00000 -2.05076</pose>
    <parent>suspension_right_main_link</parent>
    <child>right_wheel_3_link</child>
    <axis>
      <limit>
        <lower>0.00000</lower>
        <upper>0.00000</upper>
        <effort>1000.00000</effort>
        <velocity>10.00000</velocity>
      </limit>
      <xyz>0.00000 0.00000 1.00000</xyz>
    </axis>
  </joint>
  <joint name="sensor_package_link_joint" type="fixed">
    <pose relative_to="main_plate_link">-0.07970 -0.00236 -0.02071 -3.14159 0.00000 0.00000</pose>
    <parent>main_plate_link</parent>
    <child>sensor_package_link</child>
    <axis/>
  </joint>
  <joint name="suspension_left_main_link_joint" type="revolute">
    <mimic multiplier="-1.00000" offset="0.00000" joint="suspension_right_main_link_joint"/>
    <pose relative_to="main_plate_link">0.00500 -0.16509 0.09549 1.57080 0.00000 0.00000</pose>
    <parent>main_plate_link</parent>
    <child>suspension_left_main_link</child>
    <axis>
      <limit>
        <lower>-0.50000</lower>
        <upper>0.50000</upper>
        <effort>1.50000</effort>
        <velocity>0.01500</velocity>
      </limit>
      <xyz>0.00000 0.00000 1.00000</xyz>
    </axis>
  </joint>
  <joint name="suspension_left_sub_link_joint" type="revolute">
    <pose relative_to="suspension_left_main_link">0.22047 -0.07218 0.06434 -0.00000 0.00000 -0.26966</pose>
    <parent>suspension_left_main_link</parent>
    <child>suspension_left_sub_link</child>
    <axis>
      <limit>
        <lower>-0.50000</lower>
        <upper>0.50000</upper>
        <effort>5.00000</effort>
        <velocity>0.01500</velocity>
      </limit>
      <xyz>0.00000 0.00000 1.00000</xyz>
    </axis>
  </joint>
  <joint name="suspension_right_main_link_joint" type="revolute">
    <pose relative_to="main_plate_link">0.00509 0.16510 0.09582 1.57080 -0.00000 3.14159</pose>
    <parent>main_plate_link</parent>
    <child>suspension_right_main_link</child>
    <axis>
      <limit>
        <lower>-0.50000</lower>
        <upper>0.50000</upper>
        <effort>1.50000</effort>
        <velocity>0.01500</velocity>
      </limit>
      <xyz>0.00000 0.00000 1.00000</xyz>
    </axis>
  </joint>
  <joint name="suspension_right_sub_link_joint" type="revolute">
    <pose relative_to="suspension_right_main_link">-0.22047 -0.07218 0.06434 -0.00000 0.00000 0.26966</pose>
    <parent>suspension_right_main_link</parent>
    <child>suspension_right_sub_link</child>
    <axis>
      <limit>
        <lower>-0.50000</lower>
        <upper>0.50000</upper>
        <effort>5.00000</effort>
        <velocity>0.01500</velocity>
      </limit>
      <xyz>0.00000 0.00000 1.00000</xyz>
    </axis>
  </joint>
  <link name="Zed2i_link">
    <sensor name="zed2i_camera" type="camera">
      <pose relative_to="Zed2i_link">0.00000 0.00000 0.00000 0.00000 -0.00000 -0.00000</pose>
      <always_on>1</always_on>
      <visualize>0</visualize>
      <enable_metrics>0</enable_metrics>
      <camera name="zed2i_camera">
        <pose relative_to="Zed2i_link">0.00000 0.00000 0.00000 0.00000 -0.00000 -0.00000</pose>
        <horizontal_fov>1.57080</horizontal_fov>
        <image>
          <width>662</width>
          <height>376</height>
        </image>
      </camera>
    </sensor>
    <sensor name="gps" type="GPS">
      <always_on>1</always_on>
      <visualize>0</visualize>
      <enable_metrics>0</enable_metrics>
    </sensor>
    <inertial>
      <inertia>
        <ixx>0.00048</ixx>
        <ixy>0.00000</ixy>
        <ixz>0.00000</ixz>
        <iyy>0.00004</iyy>
        <iyz>0.00000</iyz>
        <izz>0.00050</izz>
      </inertia>
      <pose relative_to="Zed2i_link">0.00378 0.00106 -0.00564 0.00000 0.00000 0.00000</pose>
      <mass>0.20000</mass>
    </inertial>
    <visual name="Zed2i_visual">
      <material>
        <diffuse>0.80000 0.80000 0.80000 1.00000</diffuse>
        <specular>0.00000 0.00000 0.00000 0.00000</specular>
        <emissive>0.00000 0.00000 0.00000 1.00000</emissive>
      </material>
      <pose relative_to="Zed2i_link">0.00000 0.00000 0.00000 3.14159 1.57079 3.14159</pose>
      <geometry>
        <mesh>
          <uri>package://boden_description/meshes/dae/Zed2i.dae</uri>
          <scale>1.00000 1.00000 1.00000</scale>
        </mesh>
      </geometry>
    </visual>
  </link>
  <link name="base_link">
    <inertial>
      <inertia>
        <ixx>0.00001</ixx>
        <ixy>0.00000</ixy>
        <ixz>0.00000</ixz>
        <iyy>0.00001</iyy>
        <iyz>0.00000</iyz>
        <izz>0.00001</izz>
      </inertia>
      <pose relative_to="base_link">0.00000 0.00000 0.00000 0.00000 0.00000 0.00000</pose>
      <mass>0.00001</mass>
    </inertial>
  </link>
  <link name="battery_link">
    <inertial>
      <inertia>
        <ixx>0.04617</ixx>
        <ixy>0.00000</ixy>
        <ixz>0.00003</ixz>
        <iyy>0.04395</iyy>
        <iyz>0.00004</iyz>
        <izz>0.03884</izz>
      </inertia>
      <pose relative_to="battery_link">0.00000 0.00000 0.00144 0.00000 0.00000 0.00000</pose>
      <mass>8.00000</mass>
    </inertial>
    <visual name="battery_visual">
      <material>
        <diffuse>0.03922 0.02745 0.02745 1.00000</diffuse>
        <specular>0.00000 0.00000 0.00000 0.00000</specular>
        <emissive>0.00000 0.00000 0.00000 1.00000</emissive>
      </material>
      <pose relative_to="battery_link">0.00000 0.00000 0.00000 1.57080 0.00000 0.00000</pose>
      <geometry>
        <mesh>
          <uri>package://boden_description/meshes/dae/battery.dae</uri>
          <scale>1.00000 1.00000 1.00000</scale>
        </mesh>
      </geometry>
    </visual>
  </link>
  <link name="electronics_link">
    <inertial>
      <inertia>
        <ixx>0.00623</ixx>
        <ixy>0.00010</ixy>
        <ixz>0.00038</ixz>
        <iyy>0.00308</iyy>
        <iyz>-0.00011</iyz>
        <izz>0.00450</izz>
      </inertia>
      <pose relative_to="electronics_link">-0.01192 0.00225 0.00595 0.00000 0.00000 0.00000</pose>
      <mass>0.50000</mass>
    </inertial>
    <visual name="electronics_visual">
      <material>
        <diffuse>0.67843 0.74902 0.58039 1.00000</diffuse>
        <specular>0.00000 0.00000 0.00000 0.00000</specular>
        <emissive>0.00000 0.00000 0.00000 1.00000</emissive>
      </material>
      <pose relative_to="electronics_link">0.00000 0.00000 0.00000 1.57080 0.00000 0.00000</pose>
      <geometry>
        <mesh>
          <uri>package://boden_description/meshes/dae/electronics.dae</uri>
          <scale>1.00000 1.00000 1.00000</scale>
        </mesh>
      </geometry>
    </visual>
  </link>
  <link name="left_wheel_1_link">
    <collision name="left_wheel_1_collision">
      <pose relative_to="left_wheel_1_link">-0.00006 -0.00002 0.06622 0.00000 0.00000 0.00000</pose>
      <geometry>
        <cylinder>
          <radius>0.13329</radius>
          <length>0.10744</length>
        </cylinder>
      </geometry>
      <surface>
        <contact/>
      </surface>
    </collision>
    <inertial>
      <inertia>
        <ixx>0.00162</ixx>
        <ixy>0.00000</ixy>
        <ixz>0.00000</ixz>
        <iyy>0.00267</iyy>
        <iyz>0.00000</iyz>
        <izz>0.00162</izz>
      </inertia>
      <pose relative_to="left_wheel_1_link">-0.00006 -0.00002 0.06622 0.00000 0.00000 0.00000</pose>
      <mass>0.30000</mass>
    </inertial>
    <visual name="left_wheel_1_visual">
      <material>
        <diffuse>0.80000 0.80000 0.80000 1.00000</diffuse>
        <specular>0.00000 0.00000 0.00000 0.00000</specular>
        <emissive>0.00000 0.00000 0.00000 1.00000</emissive>
      </material>
      <pose relative_to="left_wheel_1_link">0.00000 -0.00000 -0.00000 0.00000 0.00000 0.00000</pose>
      <geometry>
        <mesh>
          <uri>package://boden_description/meshes/dae/wheel-left.dae</uri>
          <scale>1.00000 1.00000 1.00000</scale>
        </mesh>
      </geometry>
    </visual>
  </link>
  <link name="left_wheel_2_link">
    <collision name="left_wheel_2_collision">
      <pose relative_to="left_wheel_2_link">-0.00006 -0.00002 0.06622 0.00000 0.00000 0.00000</pose>
      <geometry>
        <cylinder>
          <radius>0.13329</radius>
          <length>0.10744</length>
        </cylinder>
      </geometry>
      <surface>
        <contact/>
      </surface>
    </collision>
    <inertial>
      <inertia>
        <ixx>0.00162</ixx>
        <ixy>0.00000</ixy>
        <ixz>0.00000</ixz>
        <iyy>0.00267</iyy>
        <iyz>0.00000</iyz>
        <izz>0.00162</izz>
      </inertia>
      <pose relative_to="left_wheel_2_link">-0.00006 -0.00002 0.06622 0.00000 0.00000 0.00000</pose>
      <mass>0.30000</mass>
    </inertial>
    <visual name="left_wheel_2_visual">
      <material>
        <diffuse>0.03922 0.02745 0.02745 1.00000</diffuse>
        <specular>0.00000 0.00000 0.00000 0.00000</specular>
        <emissive>0.00000 0.00000 0.00000 1.00000</emissive>
      </material>
      <pose relative_to="left_wheel_2_link">0.00000 -0.00000 -0.00000 0.00000 0.00000 0.00000</pose>
      <geometry>
        <mesh>
          <uri>package://boden_description/meshes/dae/wheel-left.dae</uri>
          <scale>1.00000 1.00000 1.00000</scale>
        </mesh>
      </geometry>
    </visual>
  </link>
  <link name="left_wheel_3_link">
    <collision name="left_wheel_3_collision">
      <pose relative_to="left_wheel_3_link">0.00004 0.00005 0.06622 -3.14159 0.00000 0.00000</pose>
      <geometry>
        <cylinder>
          <radius>0.13329</radius>
          <length>0.10744</length>
        </cylinder>
      </geometry>
      <surface>
        <contact/>
      </surface>
    </collision>
    <inertial>
      <inertia>
        <ixx>0.00162</ixx>
        <ixy>0.00000</ixy>
        <ixz>0.00000</ixz>
        <iyy>0.00267</iyy>
        <iyz>0.00000</iyz>
        <izz>0.00162</izz>
      </inertia>
      <pose relative_to="left_wheel_3_link">0.00004 0.00005 0.06622 0.00000 0.00000 0.00000</pose>
      <mass>0.30000</mass>
    </inertial>
    <visual name="left_wheel_3_visual">
      <material>
        <diffuse>0.03922 0.02745 0.02745 1.00000</diffuse>
        <specular>0.00000 0.00000 0.00000 0.00000</specular>
        <emissive>0.00000 0.00000 0.00000 1.00000</emissive>
      </material>
      <pose relative_to="left_wheel_3_link">0.00000 0.00000 -0.00000 0.00000 0.00000 0.00000</pose>
      <geometry>
        <mesh>
          <uri>package://boden_description/meshes/dae/wheel-left.dae</uri>
          <scale>1.00000 1.00000 1.00000</scale>
        </mesh>
      </geometry>
    </visual>
  </link>
  <link name="main_plate_link">
    <inertial>
      <inertia>
        <ixx>0.00100</ixx>
        <ixy>0.00000</ixy>
        <ixz>0.00000</ixz>
        <iyy>0.00100</iyy>
        <iyz>0.00000</iyz>
        <izz>0.00100</izz>
      </inertia>
      <pose relative_to="main_plate_link">-0.03928 0.00000 -0.00904 0.00000 0.00000 0.00000</pose>
      <mass>2.00000</mass>
    </inertial>
    <visual name="main_plate_visual">
      <material>
        <diffuse>0.80000 0.80000 0.80000 1.00000</diffuse>
        <specular>0.00000 0.00000 0.00000 0.00000</specular>
        <emissive>0.00000 0.00000 0.00000 1.00000</emissive>
      </material>
      <pose relative_to="main_plate_link">0.00000 0.00000 0.00674 1.57080 0.00000 0.00000</pose>
      <geometry>
        <mesh>
          <uri>package://boden_description/meshes/dae/main-plate.dae</uri>
          <scale>1.00000 1.00000 1.00000</scale>
        </mesh>
      </geometry>
    </visual>
  </link>
  <link name="right_wheel_1_link">
    <collision name="right_wheel_1_collision">
      <pose relative_to="right_wheel_1_link">0.00006 -0.00002 0.06622 -3.14159 -0.00000 0.00000</pose>
      <geometry>
        <cylinder>
          <radius>0.13329</radius>
          <length>0.10744</length>
        </cylinder>
      </geometry>
      <surface>
        <contact/>
      </surface>
    </collision>
    <inertial>
      <inertia>
        <ixx>0.00162</ixx>
        <ixy>0.00000</ixy>
        <ixz>0.00000</ixz>
        <iyy>0.00267</iyy>
        <iyz>0.00000</iyz>
        <izz>0.00162</izz>
      </inertia>
      <pose relative_to="right_wheel_1_link">0.00006 -0.00002 0.06622 0.00000 0.00000 0.00000</pose>
      <mass>0.30000</mass>
    </inertial>
    <visual name="right_wheel_1_visual">
      <material>
        <diffuse>0.03922 0.02745 0.02745 1.00000</diffuse>
        <specular>0.00000 0.00000 0.00000 0.00000</specular>
        <emissive>0.00000 0.00000 0.00000 1.00000</emissive>
      </material>
      <pose relative_to="right_wheel_1_link">0.00000 0.00000 0.00000 -3.14159 -0.00000 0.00000</pose>
      <geometry>
        <mesh>
          <uri>package://boden_description/meshes/dae/wheel-right.dae</uri>
          <scale>1.00000 1.00000 1.00000</scale>
        </mesh>
      </geometry>
    </visual>
  </link>
  <link name="right_wheel_2_link">
    <collision name="right_wheel_2_collision">
      <pose relative_to="right_wheel_2_link">0.00006 -0.00002 0.06622 3.14159 0.00000 0.00000</pose>
      <geometry>
        <cylinder>
          <radius>0.13329</radius>
          <length>0.10744</length>
        </cylinder>
      </geometry>
      <surface>
        <contact/>
      </surface>
    </collision>
    <inertial>
      <inertia>
        <ixx>0.00162</ixx>
        <ixy>0.00000</ixy>
        <ixz>0.00000</ixz>
        <iyy>0.00267</iyy>
        <iyz>0.00000</iyz>
        <izz>0.00162</izz>
      </inertia>
      <pose relative_to="right_wheel_2_link">0.00006 -0.00002 0.06622 0.00000 0.00000 0.00000</pose>
      <mass>0.30000</mass>
    </inertial>
    <visual name="right_wheel_2_visual">
      <material>
        <diffuse>0.03922 0.02745 0.02745 1.00000</diffuse>
        <specular>0.00000 0.00000 0.00000 0.00000</specular>
        <emissive>0.00000 0.00000 0.00000 1.00000</emissive>
      </material>
      <pose relative_to="right_wheel_2_link">-0.00000 -0.00000 0.00000 3.14159 0.00000 0.00000</pose>
      <geometry>
        <mesh>
          <uri>package://boden_description/meshes/dae/wheel-right.dae</uri>
          <scale>1.00000 1.00000 1.00000</scale>
        </mesh>
      </geometry>
    </visual>
  </link>
  <link name="right_wheel_3_link">
    <collision name="right_wheel_3_collision">
      <pose relative_to="right_wheel_3_link">0.00001 0.00000 0.06622 -3.14159 -0.00000 0.00000</pose>
      <geometry>
        <cylinder>
          <radius>0.13335</radius>
          <length>0.10744</length>
        </cylinder>
      </geometry>
      <surface>
        <contact/>
      </surface>
    </collision>
    <inertial>
      <inertia>
        <ixx>0.00162</ixx>
        <ixy>0.00000</ixy>
        <ixz>0.00000</ixz>
        <iyy>0.00267</iyy>
        <iyz>0.00000</iyz>
        <izz>0.00162</izz>
      </inertia>
      <pose relative_to="right_wheel_3_link">0.00001 0.00000 0.06622 0.00000 0.00000 0.00000</pose>
      <mass>0.30000</mass>
    </inertial>
    <visual name="right_wheel_3_visual">
      <material>
        <diffuse>0.03922 0.02745 0.02745 1.00000</diffuse>
        <specular>0.00000 0.00000 0.00000 0.00000</specular>
        <emissive>0.00000 0.00000 0.00000 1.00000</emissive>
      </material>
      <pose relative_to="right_wheel_3_link">0.00000 0.00000 0.00000 -3.14159 -0.00000 0.00000</pose>
      <geometry>
        <mesh>
          <uri>package://boden_description/meshes/dae/wheel-right.dae</uri>
          <scale>1.00000 1.00000 1.00000</scale>
        </mesh>
      </geometry>
    </visual>
  </link>
  <link name="sensor_package_link">
    <inertial>
      <inertia>
        <ixx>0.00129</ixx>
        <ixy>0.00000</ixy>
        <ixz>0.00001</ixz>
        <iyy>0.00052</iyy>
        <iyz>0.00001</iyz>
        <izz>0.00154</izz>
      </inertia>
      <pose relative_to="sensor_package_link">0.00247 0.00036 0.01919 0.00000 0.00000 0.00000</pose>
      <mass>0.30000</mass>
    </inertial>
    <visual name="sensor_package_visual">
      <material>
        <diffuse>0.67843 0.74902 0.58039 1.00000</diffuse>
        <specular>0.00000 0.00000 0.00000 0.00000</specular>
        <emissive>0.00000 0.00000 0.00000 1.00000</emissive>
      </material>
      <pose relative_to="sensor_package_link">0.00000 0.00000 0.00000 -1.57080 0.00000 0.00000</pose>
      <geometry>
        <mesh>
          <uri>package://boden_description/meshes/dae/sensor-package.dae</uri>
          <scale>1.00000 1.00000 1.00000</scale>
        </mesh>
      </geometry>
    </visual>
  </link>
  <link name="suspension_left_main_link">
    <inertial>
      <inertia>
        <ixx>0.03839</ixx>
        <ixy>-0.00521</ixy>
        <ixz>-0.05264</ixz>
        <iyy>0.11630</iyy>
        <iyz>-0.00362</iyz>
        <izz>0.07964</izz>
      </inertia>
      <pose relative_to="suspension_left_main_link">-0.14394 -0.11660 0.07202 0.00000 0.00000 0.00000</pose>
      <mass>2.00000</mass>
    </inertial>
    <visual name="suspension_left_main_visual">
      <material>
        <diffuse>0.03922 0.02745 0.02745 1.00000</diffuse>
        <specular>0.00000 0.00000 0.00000 0.00000</specular>
        <emissive>0.00000 0.00000 0.00000 1.00000</emissive>
      </material>
      <pose relative_to="suspension_left_main_link">0.00000 0.00000 -0.00000 3.14159 0.00000 0.00000</pose>
      <geometry>
        <mesh>
          <uri>package://boden_description/meshes/dae/suspension-left.dae</uri>
          <scale>1.00000 1.00000 1.00000</scale>
        </mesh>
      </geometry>
    </visual>
  </link>
  <link name="suspension_left_sub_link">
    <inertial>
      <inertia>
        <ixx>0.01321</ixx>
        <ixy>0.00058</ixy>
        <ixz>-0.00162</ixz>
        <iyy>0.04851</iyy>
        <iyz>-0.00201</iyz>
        <izz>0.03744</izz>
      </inertia>
      <pose relative_to="suspension_left_sub_link">0.01868 -0.09125 0.01201 0.00000 0.00000 0.00000</pose>
      <mass>2.50000</mass>
    </inertial>
    <visual name="suspension_left_sub_visual">
      <material>
        <diffuse>0.03922 0.02745 0.02745 1.00000</diffuse>
        <specular>0.00000 0.00000 0.00000 0.00000</specular>
        <emissive>0.00000 0.00000 0.00000 1.00000</emissive>
      </material>
      <pose relative_to="suspension_left_sub_link">0.00000 0.00000 0.00000 3.14159 -0.00000 -0.00000</pose>
      <geometry>
        <mesh>
          <uri>package://boden_description/meshes/dae/suspension-left-sub.dae</uri>
          <scale>1.00000 1.00000 1.00000</scale>
        </mesh>
      </geometry>
    </visual>
  </link>
  <link name="suspension_right_main_link">
    <inertial>
      <inertia>
        <ixx>0.03839</ixx>
        <ixy>0.00521</ixy>
        <ixz>-0.05264</ixz>
        <iyy>0.11630</iyy>
        <iyz>0.00362</iyz>
        <izz>0.07964</izz>
      </inertia>
      <pose relative_to="suspension_right_main_link">0.14394 -0.11660 0.07202 0.00000 0.00000 0.00000</pose>
      <mass>2.00000</mass>
    </inertial>
    <visual name="suspension_right_main_visual">
      <material>
        <diffuse>0.03922 0.02745 0.02745 1.00000</diffuse>
        <specular>0.00000 0.00000 0.00000 0.00000</specular>
        <emissive>0.00000 0.00000 0.00000 1.00000</emissive>
      </material>
      <pose relative_to="suspension_right_main_link">0.00000 0.00000 0.00000 0.00000 0.00000 -0.00000</pose>
      <geometry>
        <mesh>
          <uri>package://boden_description/meshes/dae/suspension-right.dae</uri>
          <scale>1.00000 1.00000 1.00000</scale>
        </mesh>
      </geometry>
    </visual>
  </link>
  <link name="suspension_right_sub_link">
    <inertial>
      <inertia>
        <ixx>0.01321</ixx>
        <ixy>-0.00058</ixy>
        <ixz>-0.00162</ixz>
        <iyy>0.04851</iyy>
        <iyz>0.00201</iyz>
        <izz>0.03744</izz>
      </inertia>
      <pose relative_to="suspension_right_sub_link">-0.01868 -0.09125 0.01201 0.00000 0.00000 0.00000</pose>
      <mass>2.50000</mass>
    </inertial>
    <visual name="suspension_right_sub_visual">
      <material>
        <diffuse>0.80000 0.80000 0.80000 1.00000</diffuse>
        <specular>0.00000 0.00000 0.00000 0.00000</specular>
        <emissive>0.00000 0.00000 0.00000 1.00000</emissive>
      </material>
      <pose relative_to="suspension_right_sub_link">-0.00000 -0.00000 0.00000 -0.00000 0.00000 0.00000</pose>
      <geometry>
        <mesh>
          <uri>package://boden_description/meshes/dae/suspension-right-sub.dae</uri>
          <scale>1.00000 1.00000 1.00000</scale>
        </mesh>
      </geometry>
    </visual>
  </link>
</model>
</sdf>