<robot name="assem" version="1.0">
  <joint name="Cube_link_joint" type="fixed">
    <origin rpy="0.00000 0.00000 0.00000" xyz="0.01837 -0.07980 -0.04656"/>
    <parent link="chassisAssembly_-_electronicsHousing-1_Rough_6_Pin_Pannel_C.002"/>
    <child link="Cube_link"/>
  </joint>
  <joint name="LongMotorAssem_V4 - Rough Shaft_V2-1.001_link_joint" type="continuous">
    <limit lower="0.00000" upper="0.00000" effort="0.00000" velocity="0.00000"/>
    <origin rpy="0.00000 0.00000 -2.34661" xyz="0.12032 -0.18908 0.02638"/>
    <parent link="suspensionAssemblyMirror_-_bogieCenterBracket_Outside-6_link"/>
    <child link="LongMotorAssem_V4_-_Rough_Shaft_V2-1.001_link"/>
    <axis xyz="0.00000 0.00000 1.00000"/>
  </joint>
  <joint name="LongMotorAssem_V4 - Rough Shaft_V2-1.002_link_joint" type="continuous">
    <limit lower="0.00000" upper="0.00000" effort="0.00000" velocity="0.00000"/>
    <origin rpy="-0.00000 0.00000 2.19125" xyz="-0.17866 -0.06537 0.02638"/>
    <parent link="suspensionAssemblyMirror_-_bogieCenterBracket_Outside-6_link"/>
    <child link="LongMotorAssem_V4_-_Rough_Shaft_V2-1.002_link"/>
    <axis xyz="0.00000 0.00000 1.00000"/>
  </joint>
  <joint name="LongMotorAssem_V4 - Rough Shaft_V2-1.003_link_joint" type="continuous">
    <limit lower="0.00000" upper="0.00000" effort="0.00000" velocity="0.00000"/>
    <origin rpy="0.00000 0.00000 2.05076" xyz="-0.29512 -0.20932 0.09071"/>
    <parent link="suspensionAssemblyMirror_-_RockerArmBack-7.001_link"/>
    <child link="LongMotorAssem_V4_-_Rough_Shaft_V2-1.003_link"/>
    <axis xyz="0.00000 0.00000 1.00000"/>
  </joint>
  <joint name="LongMotorAssem_V4 - Rough Shaft_V2-1.004_link_joint" type="continuous">
    <limit lower="0.00000" upper="0.00000" effort="0.00000" velocity="0.00000"/>
    <origin rpy="-0.00000 0.00000 2.34661" xyz="-0.12032 -0.18908 0.02638"/>
    <parent link="suspensionAssemblyMirror_-_bogieCenterBracket_Outside-6.001_lin"/>
    <child link="LongMotorAssem_V4_-_Rough_Shaft_V2-1.004_link"/>
    <axis xyz="0.00000 0.00000 1.00000"/>
  </joint>
  <joint name="LongMotorAssem_V4 - Rough Shaft_V2-1.005_link_joint" type="continuous">
    <limit lower="0.00000" upper="0.00000" effort="0.00000" velocity="0.00000"/>
    <origin rpy="-0.00000 0.00000 0.26966" xyz="0.17866 -0.06537 0.02638"/>
    <parent link="suspensionAssemblyMirror_-_bogieCenterBracket_Outside-6.001_lin"/>
    <child link="LongMotorAssem_V4_-_Rough_Shaft_V2-1.005_link"/>
    <axis xyz="0.00000 0.00000 1.00000"/>
  </joint>
  <joint name="LongMotorAssem_V4 - Rough Shaft_V2-1_link_joint" type="continuous">
    <limit lower="0.00000" upper="0.00000" effort="0.00000" velocity="0.00000"/>
    <origin rpy="-0.00000 -0.00000 -2.05076" xyz="0.29512 -0.20932 0.09071"/>
    <parent link="suspensionAssemblyMirror_-_RockerArmBack-7_link"/>
    <child link="LongMotorAssem_V4_-_Rough_Shaft_V2-1_link"/>
    <axis xyz="0.00000 0.00000 1.00000"/>
  </joint>
  <joint name="Zed2-i_link_joint" type="fixed">
    <origin rpy="1.57080 0.00000 -1.57080" xyz="-0.08420 0.00894 0.08299"/>
    <parent link="chassisAssembly_-_electronicsHousing-1_Rough_6_Pin_Pannel_C.002"/>
    <child link="Zed2-i_link"/>
  </joint>
  <joint name="chassisAssembly - electronicsHousing-1 Rough 6 Pin Pannel C.002_joint" type="fixed">
    <origin rpy="0.00000 0.00000 0.00000" xyz="-0.08592 -0.00513 0.39248"/>
    <parent link="chassisAssembly_-_chassisFrameShort-2_link"/>
    <child link="chassisAssembly_-_electronicsHousing-1_Rough_6_Pin_Pannel_C.002"/>
  </joint>
  <joint name="chassisAssembly - roverBattery-1_link_joint" type="fixed">
    <origin rpy="0.00000 0.00000 0.00000" xyz="0.05208 0.00000 0.34177"/>
    <parent link="chassisAssembly_-_chassisFrameShort-2_link"/>
    <child link="chassisAssembly_-_roverBattery-1_link"/>
  </joint>
  <joint name="chassisAssembly - sensorPackageEnclosure-1_link_joint" type="fixed">
    <origin rpy="-3.14159 0.00000 0.00000" xyz="-0.07970 -0.00236 0.26479"/>
    <parent link="chassisAssembly_-_chassisFrameShort-2_link"/>
    <child link="chassisAssembly_-_sensorPackageEnclosure-1_link"/>
  </joint>
  <joint name="suspensionAssemblyMirror - RockerArmBack-7.001_link_joint" type="revolute">
    <limit lower="-3.14000" upper="3.14000" effort="0.00000" velocity="0.00000"/>
    <origin rpy="1.57080 -0.00000 0.00000" xyz="0.00500 -0.16509 0.38099"/>
    <parent link="chassisAssembly_-_chassisFrameShort-2_link"/>
    <child link="suspensionAssemblyMirror_-_RockerArmBack-7.001_link"/>
    <axis xyz="0.00000 0.00000 1.00000"/>
  </joint>
  <joint name="suspensionAssemblyMirror - RockerArmBack-7_link_joint" type="revolute">
    <limit lower="-3.14000" upper="3.14000" effort="0.00000" velocity="0.00000"/>
    <origin rpy="1.57080 0.00000 3.14159" xyz="0.00509 0.16510 0.38132"/>
    <parent link="chassisAssembly_-_chassisFrameShort-2_link"/>
    <child link="suspensionAssemblyMirror_-_RockerArmBack-7_link"/>
    <axis xyz="0.00000 0.00000 1.00000"/>
  </joint>
  <joint name="suspensionAssemblyMirror - bogieCenterBracket_Outside-6.001_lin_joint" type="revolute">
    <limit lower="-3.14000" upper="3.14000" effort="0.00000" velocity="0.00000"/>
    <origin rpy="0.00000 0.00000 -0.26966" xyz="0.22047 -0.07218 0.06434"/>
    <parent link="suspensionAssemblyMirror_-_RockerArmBack-7.001_link"/>
    <child link="suspensionAssemblyMirror_-_bogieCenterBracket_Outside-6.001_lin"/>
    <axis xyz="0.00000 0.00000 1.00000"/>
  </joint>
  <joint name="suspensionAssemblyMirror - bogieCenterBracket_Outside-6_link_joint" type="revolute">
    <limit lower="-3.14000" upper="3.14000" effort="0.00000" velocity="0.00000"/>
    <origin rpy="0.00000 0.00000 0.26966" xyz="-0.22047 -0.07218 0.06434"/>
    <parent link="suspensionAssemblyMirror_-_RockerArmBack-7_link"/>
    <child link="suspensionAssemblyMirror_-_bogieCenterBracket_Outside-6_link"/>
    <axis xyz="0.00000 0.00000 1.00000"/>
  </joint>
  <link name="Cube_link"/>
  <link name="LongMotorAssem_V4_-_Rough_Shaft_V2-1.001_link">
    <collision name="LongMotorAssem_V4 - Rough Shaft_V2-1.001_collision">
      <origin rpy="-3.14159 0.00000 0.00000" xyz="0.00006 -0.00002 0.06622"/>
      <geometry>
        <cylinder radius="0.13329" length="0.10744"/>
      </geometry>
    </collision>
    <inertial>
      <inertia ixx="0.00162" ixy="0.00000" ixz="0.00000" iyy="0.00267" iyz="0.00000" izz="0.00162"/>
      <origin rpy="0.00000 0.00000 0.00000" xyz="0.00006 -0.00002 0.06622"/>
      <mass value="0.30000"/>
    </inertial>
    <visual name="LongMotorAssem_V4 - Rough Shaft_V2-1.001">
      <origin rpy="-3.14159 0.00000 0.00000" xyz="0.00000 -0.00000 0.00000"/>
      <material name="Metal10"/>
      <geometry>
        <mesh filename="package://meshes/dae/LongMotorAssem_V4 - Rough Shaft_V2-1.001.dae" scale="1.00000 1.00000 1.00000"/>
      </geometry>
    </visual>
  </link>
  <link name="LongMotorAssem_V4_-_Rough_Shaft_V2-1.002_link">
    <collision name="LongMotorAssem_V4 - Rough Shaft_V2-1.002_collision">
      <origin rpy="3.14159 0.00000 0.00000" xyz="0.00006 -0.00002 0.06622"/>
      <geometry>
        <cylinder radius="0.13329" length="0.10744"/>
      </geometry>
    </collision>
    <inertial>
      <inertia ixx="0.00162" ixy="0.00000" ixz="0.00000" iyy="0.00267" iyz="-0.00000" izz="0.00162"/>
      <origin rpy="0.00000 0.00000 0.00000" xyz="0.00006 -0.00002 0.06622"/>
      <mass value="0.30000"/>
    </inertial>
    <visual name="LongMotorAssem_V4 - Rough Shaft_V2-1.002">
      <origin rpy="3.14159 0.00000 0.00000" xyz="0.00000 0.00000 0.00000"/>
      <material name="Metal10"/>
      <geometry>
        <mesh filename="package://meshes/dae/LongMotorAssem_V4 - Rough Shaft_V2-1.002.dae" scale="1.00000 1.00000 1.00000"/>
      </geometry>
    </visual>
  </link>
  <link name="LongMotorAssem_V4_-_Rough_Shaft_V2-1.003_link">
    <collision name="LongMotorAssem_V4 - Rough Shaft_V2-1.003_collision">
      <origin rpy="0.00000 -0.00000 -0.00000" xyz="-0.00006 -0.00002 0.06622"/>
      <geometry>
        <cylinder radius="0.13329" length="0.10744"/>
      </geometry>
    </collision>
    <inertial>
      <inertia ixx="0.00162" ixy="-0.00000" ixz="0.00000" iyy="0.00267" iyz="-0.00000" izz="0.00162"/>
      <origin rpy="0.00000 0.00000 0.00000" xyz="-0.00006 -0.00002 0.06622"/>
      <mass value="0.30000"/>
    </inertial>
    <visual name="LongMotorAssem_V4 - Rough Shaft_V2-1.003">
      <origin rpy="0.00000 -0.00000 -0.00000" xyz="-0.00000 0.00000 0.00000"/>
      <material name="Metal10"/>
      <geometry>
        <mesh filename="package://meshes/dae/LongMotorAssem_V4 - Rough Shaft_V2-1.003.dae" scale="1.00000 1.00000 1.00000"/>
      </geometry>
    </visual>
  </link>
  <link name="LongMotorAssem_V4_-_Rough_Shaft_V2-1.004_link">
    <collision name="LongMotorAssem_V4 - Rough Shaft_V2-1.004_collision">
      <origin rpy="0.00000 0.00000 0.00000" xyz="-0.00006 -0.00002 0.06622"/>
      <geometry>
        <cylinder radius="0.13329" length="0.10744"/>
      </geometry>
    </collision>
    <inertial>
      <inertia ixx="0.00162" ixy="-0.00000" ixz="0.00000" iyy="0.00267" iyz="-0.00000" izz="0.00162"/>
      <origin rpy="0.00000 0.00000 0.00000" xyz="-0.00006 -0.00002 0.06622"/>
      <mass value="0.30000"/>
    </inertial>
    <visual name="LongMotorAssem_V4 - Rough Shaft_V2-1.004">
      <origin rpy="0.00000 0.00000 0.00000" xyz="-0.00000 -0.00000 -0.00000"/>
      <material name="Metal10"/>
      <geometry>
        <mesh filename="package://meshes/dae/LongMotorAssem_V4 - Rough Shaft_V2-1.004.dae" scale="1.00000 1.00000 1.00000"/>
      </geometry>
    </visual>
  </link>
  <link name="LongMotorAssem_V4_-_Rough_Shaft_V2-1.005_link">
    <collision name="LongMotorAssem_V4 - Rough Shaft_V2-1.005_collision">
      <origin rpy="-3.14159 0.00000 -0.00000" xyz="0.00004 0.00005 0.06622"/>
      <geometry>
        <cylinder radius="0.13329" length="0.10744"/>
      </geometry>
    </collision>
    <inertial>
      <inertia ixx="0.00162" ixy="0.00000" ixz="0.00000" iyy="0.00267" iyz="0.00000" izz="0.00162"/>
      <origin rpy="0.00000 0.00000 0.00000" xyz="0.00004 0.00005 0.06622"/>
      <mass value="0.30000"/>
    </inertial>
    <visual name="LongMotorAssem_V4 - Rough Shaft_V2-1.005">
      <origin rpy="1.57080 -0.00000 -0.00000" xyz="0.00000 -0.00000 -0.00000"/>
      <material name="Metal10"/>
      <geometry>
        <mesh filename="package://meshes/dae/LongMotorAssem_V4 - Rough Shaft_V2-1.006.dae" scale="1.00000 1.00000 1.00000"/>
      </geometry>
    </visual>
  </link>
  <link name="LongMotorAssem_V4_-_Rough_Shaft_V2-1_link">
    <collision name="LongMotorAssem_V4 - Rough Shaft_V2-1_collision">
      <origin rpy="-3.14159 0.00000 0.00000" xyz="0.00001 -0.00000 0.06622"/>
      <geometry>
        <cylinder radius="0.13335" length="0.10744"/>
      </geometry>
    </collision>
    <inertial>
      <inertia ixx="0.00162" ixy="0.00000" ixz="0.00000" iyy="0.00267" iyz="0.00000" izz="0.00162"/>
      <origin rpy="0.00000 0.00000 0.00000" xyz="0.00001 -0.00000 0.06622"/>
      <mass value="0.30000"/>
    </inertial>
    <visual name="LongMotorAssem_V4 - Rough Shaft_V2-1">
      <origin rpy="-3.14159 0.00000 0.00000" xyz="-0.00000 0.00000 0.00000"/>
      <material name="Metal10"/>
      <geometry>
        <mesh filename="package://meshes/dae/LongMotorAssem_V4 - Rough Shaft_V2-1.dae" scale="1.00000 1.00000 1.00000"/>
      </geometry>
    </visual>
  </link>
  <link name="Zed2-i_link">
    <inertial>
      <inertia ixx="0.00048" ixy="0.00000" ixz="-0.00000" iyy="0.00004" iyz="0.00000" izz="0.00050"/>
      <origin rpy="0.00000 0.00000 0.00000" xyz="0.00378 0.00106 -0.00564"/>
      <mass value="0.20000"/>
    </inertial>
    <visual name="Zed2-i">
      <origin rpy="0.00000 1.57080 0.00000" xyz="0.00000 0.00000 -0.00000"/>
      <material name="Glass"/>
      <geometry>
        <mesh filename="package://meshes/dae/Zed2-i.dae" scale="1.00000 1.00000 1.00000"/>
      </geometry>
    </visual>
  </link>
  <link name="chassisAssembly_-_chassisFrameShort-2_link">
    <inertial>
      <inertia ixx="0.00100" ixy="0.00000" ixz="0.00000" iyy="0.00100" iyz="0.00000" izz="0.00100"/>
      <origin rpy="0.00000 0.00000 0.00000" xyz="0.00000 0.00000 0.00000"/>
      <mass value="2.00000"/>
    </inertial>
    <visual name="chassisAssembly - chassisFrameShort-2">
      <origin rpy="1.57080 0.00000 0.00000" xyz="0.00000 0.00000 0.29224"/>
      <material name="Metal28"/>
      <geometry>
        <mesh filename="package://meshes/dae/chassisAssembly - chassisFrameShort-2.dae" scale="1.00000 1.00000 1.00000"/>
      </geometry>
    </visual>
  </link>
  <link name="chassisAssembly_-_electronicsHousing-1_Rough_6_Pin_Pannel_C.002">
    <inertial>
      <inertia ixx="0.00623" ixy="0.00010" ixz="0.00038" iyy="0.00308" iyz="-0.00011" izz="0.00450"/>
      <origin rpy="0.00000 0.00000 0.00000" xyz="-0.01192 0.00225 0.00595"/>
      <mass value="0.50000"/>
    </inertial>
    <visual name="chassisAssembly - electronicsHousing-1 Rough 6 Pin Pannel C.001">
      <origin rpy="1.57080 0.00000 0.00000" xyz="0.00000 0.00000 0.00000"/>
      <material name="Plastic03"/>
      <geometry>
        <mesh filename="package://meshes/dae/chassisAssembly - electronicsHousing-1 Rough 6 Pin Pannel C.001.dae" scale="1.00000 1.00000 1.00000"/>
      </geometry>
    </visual>
  </link>
  <link name="chassisAssembly_-_roverBattery-1_link">
    <inertial>
      <inertia ixx="0.04617" ixy="-0.00000" ixz="0.00003" iyy="0.04395" iyz="0.00004" izz="0.03884"/>
      <origin rpy="0.00000 0.00000 0.00000" xyz="-0.00000 -0.00000 0.00144"/>
      <mass value="8.00000"/>
    </inertial>
    <visual name="chassisAssembly - roverBattery-1">
      <origin rpy="1.57080 0.00000 0.00000" xyz="0.00000 0.00000 -0.00000"/>
      <material name="Plastic04"/>
      <geometry>
        <mesh filename="package://meshes/dae/chassisAssembly - roverBattery-1.dae" scale="1.00000 1.00000 1.00000"/>
      </geometry>
    </visual>
  </link>
  <link name="chassisAssembly_-_sensorPackageEnclosure-1_link">
    <inertial>
      <inertia ixx="0.00129" ixy="0.00000" ixz="0.00001" iyy="0.00052" iyz="0.00001" izz="0.00154"/>
      <origin rpy="0.00000 0.00000 0.00000" xyz="0.00247 0.00036 0.01919"/>
      <mass value="0.30000"/>
    </inertial>
    <visual name="chassisAssembly - sensorPackageEnclosure-1">
      <origin rpy="-1.57080 0.00000 0.00000" xyz="0.00000 -0.00000 0.00000"/>
      <material name="Plastic04"/>
      <geometry>
        <mesh filename="package://meshes/dae/chassisAssembly - sensorPackageEnclosure-1.dae" scale="1.00000 1.00000 1.00000"/>
      </geometry>
    </visual>
  </link>
  <link name="suspensionAssemblyMirror_-_RockerArmBack-7.001_link">
    <inertial>
      <inertia ixx="0.03839" ixy="-0.00521" ixz="-0.05264" iyy="0.11630" iyz="-0.00362" izz="0.07964"/>
      <origin rpy="0.00000 0.00000 0.00000" xyz="-0.14394 -0.11660 0.07202"/>
      <mass value="2.00000"/>
    </inertial>
    <visual name="suspensionAssemblyMirror - RockerArmBack-7.001">
      <origin rpy="3.14159 0.00000 0.00000" xyz="0.00000 0.00000 -0.00000"/>
      <material name="Metal28"/>
      <geometry>
        <mesh filename="package://meshes/dae/suspensionAssemblyMirror - RockerArmBack-7.001.dae" scale="1.00000 1.00000 1.00000"/>
      </geometry>
    </visual>
  </link>
  <link name="suspensionAssemblyMirror_-_RockerArmBack-7_link">
    <inertial>
      <inertia ixx="0.03839" ixy="0.00521" ixz="-0.05264" iyy="0.11630" iyz="0.00362" izz="0.07964"/>
      <origin rpy="0.00000 0.00000 0.00000" xyz="0.14394 -0.11660 0.07202"/>
      <mass value="2.00000"/>
    </inertial>
    <visual name="suspensionAssemblyMirror - RockerArmBack-7">
      <origin rpy="-0.00000 0.00000 -0.00000" xyz="0.00000 -0.00000 -0.00000"/>
      <material name="Metal28"/>
      <geometry>
        <mesh filename="package://meshes/dae/suspensionAssemblyMirror - RockerArmBack-7.dae" scale="1.00000 1.00000 1.00000"/>
      </geometry>
    </visual>
  </link>
  <link name="suspensionAssemblyMirror_-_bogieCenterBracket_Outside-6.001_lin">
    <inertial>
      <inertia ixx="0.01321" ixy="0.00058" ixz="-0.00162" iyy="0.04851" iyz="-0.00201" izz="0.03744"/>
      <origin rpy="0.00000 0.00000 0.00000" xyz="0.01868 -0.09125 0.01201"/>
      <mass value="2.50000"/>
    </inertial>
    <visual name="suspensionAssemblyMirror - bogieCenterBracket_Outside-6.001">
      <origin rpy="3.14159 -0.00000 -0.00000" xyz="0.00000 -0.00000 -0.00000"/>
      <material name="Metal28"/>
      <geometry>
        <mesh filename="package://meshes/dae/suspensionAssemblyMirror - bogieCenterBracket_Outside-6.001.dae" scale="1.00000 1.00000 1.00000"/>
      </geometry>
    </visual>
  </link>
  <link name="suspensionAssemblyMirror_-_bogieCenterBracket_Outside-6_link">
    <inertial>
      <inertia ixx="0.01321" ixy="-0.00058" ixz="-0.00162" iyy="0.04851" iyz="0.00201" izz="0.03744"/>
      <origin rpy="0.00000 0.00000 0.00000" xyz="-0.01868 -0.09125 0.01201"/>
      <mass value="2.50000"/>
    </inertial>
    <visual name="suspensionAssemblyMirror - bogieCenterBracket_Outside-6">
      <origin rpy="-0.00000 -0.00000 0.00000" xyz="-0.00000 0.00000 -0.00000"/>
      <material name="Metal28"/>
      <geometry>
        <mesh filename="package://meshes/dae/suspensionAssemblyMirror - bogieCenterBracket_Outside-6.dae" scale="1.00000 1.00000 1.00000"/>
      </geometry>
    </visual>
  </link>
  <material name="Glass">
    <color rgba="0.80000 0.80000 0.80000 1.00000"/>
  </material>
  <material name="Metal10">
    <color rgba="0.80000 0.80000 0.80000 1.00000"/>
  </material>
  <material name="Metal28">
    <color rgba="0.80000 0.80000 0.80000 1.00000"/>
  </material>
  <material name="Plastic03">
    <color rgba="0.80000 0.80000 0.80000 1.00000"/>
  </material>
  <material name="Plastic04">
    <color rgba="0.80000 0.80000 0.80000 1.00000"/>
  </material>
</robot>