<?xml version="1.0"?>
<robot xmlns:xacro="http://www.ros.org/wiki/xacro">
<xacro:macro name="bodenbot" params="prefix">
  <joint name="Zed2i_link_joint" type="fixed">
    <origin rpy="0.00000 0.00682 3.14159" xyz="-0.08420 0.00894 0.08299"/>
    <parent link="electronics_link"/>
    <child link="Zed2i_link"/>
  </joint>
  <joint name="base_link_joint" type="fixed">
    <origin rpy="0.00000 0.00000 0.00000" xyz="0.00000 0.00000 -0.23899"/>
    <parent link="main_plate_link"/>
    <child link="base_link"/>
  </joint>
  <joint name="battery_link_joint" type="fixed">
    <origin rpy="0.00000 0.00000 -3.14159" xyz="-0.09286 -0.00214 0.05627"/>
    <parent link="main_plate_link"/>
    <child link="battery_link"/>
  </joint>
  <joint name="electronics_link_joint" type="fixed">
    <origin rpy="0.00000 0.00000 -3.14159" xyz="0.04514 0.00299 0.10698"/>
    <parent link="main_plate_link"/>
    <child link="electronics_link"/>
  </joint>
  <joint name="left_wheel_1_link_joint" type="continuous">
    <limit lower="0.00000" upper="0.00000" effort="1000.00000" velocity="10.00000"/>
    <origin rpy="0.00000 -0.00000 2.05076" xyz="-0.29512 -0.20932 0.09071"/>
    <parent link="suspension_left_main_link"/>
    <child link="left_wheel_1_link"/>
    <axis xyz="0.00000 0.00000 1.00000"/>
  </joint>
  <joint name="left_wheel_2_link_joint" type="continuous">
    <limit lower="0.00000" upper="0.00000" effort="1000.00000" velocity="10.00000"/>
    <origin rpy="0.00000 0.00000 2.34661" xyz="-0.12032 -0.18908 0.02638"/>
    <parent link="suspension_left_sub_link"/>
    <child link="left_wheel_2_link"/>
    <axis xyz="0.00000 0.00000 1.00000"/>
  </joint>
  <joint name="left_wheel_3_link_joint" type="continuous">
    <limit lower="0.00000" upper="0.00000" effort="1000.00000" velocity="10.00000"/>
    <origin rpy="0.00000 0.00000 0.26966" xyz="0.17866 -0.06537 0.02638"/>
    <parent link="suspension_left_sub_link"/>
    <child link="left_wheel_3_link"/>
    <axis xyz="0.00000 0.00000 1.00000"/>
  </joint>
  <joint name="right_wheel_1_link_joint" type="continuous">
    <limit lower="0.00000" upper="0.00000" effort="1000.00000" velocity="10.00000"/>
    <origin rpy="-0.00000 0.00000 -2.34661" xyz="0.12032 -0.18908 0.02638"/>
    <parent link="suspension_right_sub_link"/>
    <child link="right_wheel_1_link"/>
    <axis xyz="0.00000 0.00000 -1.00000"/>
  </joint>
  <joint name="right_wheel_2_link_joint" type="continuous">
    <limit lower="0.00000" upper="0.00000" effort="1000.00000" velocity="10.00000"/>
    <origin rpy="0.00000 -0.00000 2.19125" xyz="-0.17866 -0.06537 0.02638"/>
    <parent link="suspension_right_sub_link"/>
    <child link="right_wheel_2_link"/>
    <axis xyz="0.00000 0.00000 -1.00000"/>
  </joint>
  <joint name="right_wheel_3_link_joint" type="continuous">
    <limit lower="0.00000" upper="0.00000" effort="1000.00000" velocity="10.00000"/>
    <origin rpy="-0.00000 0.00000 -2.05076" xyz="0.29512 -0.20932 0.09071"/>
    <parent link="suspension_right_main_link"/>
    <child link="right_wheel_3_link"/>
    <axis xyz="0.00000 0.00000 -1.00000"/>
  </joint>
  <joint name="sensor_package_link_joint" type="fixed">
    <origin rpy="-3.14159 0.00000 -3.14159" xyz="0.03892 0.00022 -0.02071"/>
    <parent link="main_plate_link"/>
    <child link="sensor_package_link"/>
  </joint>
  <joint name="suspension_left_main_link_joint" type="revolute">
    <limit lower="-0.50000" upper="0.50000" effort="1.50000" velocity="0.01500"/>
    <mimic multiplier="-1.00000" offset="0.00000" joint="suspension_right_main_link_joint"/>
    <origin rpy="1.57080 0.00000 -3.14159" xyz="-0.04578 0.16295 0.09549"/>
    <parent link="main_plate_link"/>
    <child link="suspension_left_main_link"/>
    <axis xyz="0.00000 0.00000 1.00000"/>
  </joint>
  <joint name="suspension_left_sub_link_joint" type="revolute">
    <limit lower="-0.50000" upper="0.50000" effort="5.00000" velocity="0.01500"/>
    <origin rpy="-0.00000 0.00000 -0.26966" xyz="0.22047 -0.07218 0.06434"/>
    <parent link="suspension_left_main_link"/>
    <child link="suspension_left_sub_link"/>
    <axis xyz="0.00000 0.00000 1.00000"/>
  </joint>
  <joint name="suspension_right_main_link_joint" type="revolute">
    <limit lower="-0.50000" upper="0.50000" effort="1.50000" velocity="0.01500"/>
    <origin rpy="1.57080 -0.00000 -0.00000" xyz="-0.04587 -0.16724 0.09582"/>
    <parent link="main_plate_link"/>
    <child link="suspension_right_main_link"/>
    <axis xyz="0.00000 0.00000 1.00000"/>
  </joint>
  <joint name="suspension_right_sub_link_joint" type="revolute">
    <limit lower="-0.50000" upper="0.50000" effort="5.00000" velocity="0.01500"/>
    <origin rpy="-0.00000 0.00000 0.26966" xyz="-0.22047 -0.07218 0.06434"/>
    <parent link="suspension_right_main_link"/>
    <child link="suspension_right_sub_link"/>
    <axis xyz="0.00000 0.00000 1.00000"/>
  </joint>
  <link name="Zed2i_link">
    <inertial>
      <inertia ixx="0.00048" ixy="0.00000" ixz="0.00000" iyy="0.00004" iyz="0.00000" izz="0.00050"/>
      <origin rpy="0.00000 0.00000 0.00000" xyz="0.00378 0.00106 -0.00564"/>
      <mass value="0.20000"/>
    </inertial>
    <visual name="Zed2i_visual">
      <origin rpy="1.57080 -0.00000 3.14159" xyz="-0.00000 -0.00000 -0.00000"/>
      <material name="Glass"/>
      <geometry>
        <mesh filename="package://bodenbot/description/meshes/dae/Zed2i.dae" scale="1.00000 1.00000 1.00000"/>
      </geometry>
    </visual>
  </link>
  <link name="base_link">
    <inertial>
      <inertia ixx="0.00001" ixy="0.00000" ixz="0.00000" iyy="0.00001" iyz="0.00000" izz="0.00001"/>
      <origin rpy="0.00000 0.00000 0.00000" xyz="0.00000 0.00000 0.00000"/>
      <mass value="0.00001"/>
    </inertial>
  </link>
  <link name="battery_link">
    <inertial>
      <inertia ixx="0.04617" ixy="0.00000" ixz="0.00003" iyy="0.04395" iyz="0.00004" izz="0.03884"/>
      <origin rpy="0.00000 0.00000 0.00000" xyz="0.00000 0.00000 0.00144"/>
      <mass value="8.00000"/>
    </inertial>
    <visual name="battery_visual">
      <origin rpy="1.57080 0.00000 0.00000" xyz="0.00000 0.00000 0.00000"/>
      <material name="Rubber"/>
      <geometry>
        <mesh filename="package://bodenbot/description/meshes/dae/battery.dae" scale="1.00000 1.00000 1.00000"/>
      </geometry>
    </visual>
  </link>
  <link name="electronics_link">
    <inertial>
      <inertia ixx="0.00623" ixy="0.00010" ixz="0.00038" iyy="0.00308" iyz="-0.00011" izz="0.00450"/>
      <origin rpy="0.00000 0.00000 0.00000" xyz="-0.01192 0.00225 0.00595"/>
      <mass value="0.50000"/>
    </inertial>
    <visual name="electronics_visual">
      <origin rpy="1.57080 0.00000 0.00000" xyz="-0.00000 0.00000 0.00000"/>
      <material name="Plastic"/>
      <geometry>
        <mesh filename="package://bodenbot/description/meshes/dae/electronics.dae" scale="1.00000 1.00000 1.00000"/>
      </geometry>
    </visual>
  </link>
  <link name="left_wheel_1_link">
    <collision name="left_wheel_1_collision">
      <origin rpy="-0.00000 0.00000 0.00000" xyz="-0.00006 -0.00002 0.06622"/>
      <geometry>
        <cylinder radius="0.13329" length="0.10744"/>
      </geometry>
    </collision>
    <inertial>
      <inertia ixx="0.00162" ixy="0.00000" ixz="0.00000" iyy="0.00267" iyz="0.00000" izz="0.00162"/>
      <origin rpy="0.00000 0.00000 0.00000" xyz="-0.00006 -0.00002 0.06622"/>
      <mass value="0.30000"/>
    </inertial>
    <visual name="left_wheel_1_visual">
      <origin rpy="-0.00000 0.00000 0.00000" xyz="-0.00000 0.00000 0.00000"/>
      <material name="Metal"/>
      <geometry>
        <mesh filename="package://bodenbot/description/meshes/dae/wheel_left.dae" scale="1.00000 1.00000 1.00000"/>
      </geometry>
    </visual>
  </link>
  <link name="left_wheel_2_link">
    <collision name="left_wheel_2_collision">
      <origin rpy="0.00000 0.00000 0.00000" xyz="-0.00006 -0.00002 0.06622"/>
      <geometry>
        <cylinder radius="0.13329" length="0.10744"/>
      </geometry>
    </collision>
    <inertial>
      <inertia ixx="0.00162" ixy="0.00000" ixz="0.00000" iyy="0.00267" iyz="0.00000" izz="0.00162"/>
      <origin rpy="0.00000 0.00000 0.00000" xyz="-0.00006 -0.00002 0.06622"/>
      <mass value="0.30000"/>
    </inertial>
    <visual name="left_wheel_2_visual">
      <origin rpy="0.00000 0.00000 0.00000" xyz="0.00000 -0.00000 -0.00000"/>
      <material name="Rubber"/>
      <geometry>
        <mesh filename="package://bodenbot/description/meshes/dae/wheel_left.dae" scale="1.00000 1.00000 1.00000"/>
      </geometry>
    </visual>
  </link>
  <link name="left_wheel_3_link">
    <collision name="left_wheel_3_collision">
      <origin rpy="-3.14159 0.00000 0.00000" xyz="0.00004 0.00005 0.06622"/>
      <geometry>
        <cylinder radius="0.13329" length="0.10744"/>
      </geometry>
    </collision>
    <inertial>
      <inertia ixx="0.00162" ixy="0.00000" ixz="0.00000" iyy="0.00267" iyz="0.00000" izz="0.00162"/>
      <origin rpy="0.00000 0.00000 0.00000" xyz="0.00004 0.00005 0.06622"/>
      <mass value="0.30000"/>
    </inertial>
    <visual name="left_wheel_3_visual">
      <origin rpy="0.00000 0.00000 0.00000" xyz="0.00000 0.00000 -0.00000"/>
      <material name="Rubber"/>
      <geometry>
        <mesh filename="package://bodenbot/description/meshes/dae/wheel_left.dae" scale="1.00000 1.00000 1.00000"/>
      </geometry>
    </visual>
  </link>
  <link name="main_plate_link">
    <inertial>
      <inertia ixx="0.00100" ixy="0.00000" ixz="0.00000" iyy="0.00100" iyz="0.00000" izz="0.00100"/>
      <origin rpy="0.00000 0.00000 0.00000" xyz="-0.00150 -0.00214 -0.00904"/>
      <mass value="2.00000"/>
    </inertial>
    <visual name="main_plate_visual">
      <origin rpy="1.57080 0.00000 -3.14159" xyz="-0.04078 -0.00214 0.00674"/>
      <material name="Metal"/>
      <geometry>
        <mesh filename="package://bodenbot/description/meshes/dae/main_plate.dae" scale="1.00000 1.00000 1.00000"/>
      </geometry>
    </visual>
  </link>
  <link name="right_wheel_1_link">
    <collision name="right_wheel_1_collision">
      <origin rpy="-3.14159 -0.00000 0.00000" xyz="0.00006 -0.00002 0.06622"/>
      <geometry>
        <cylinder radius="0.13329" length="0.10744"/>
      </geometry>
    </collision>
    <inertial>
      <inertia ixx="0.00162" ixy="0.00000" ixz="0.00000" iyy="0.00267" iyz="0.00000" izz="0.00162"/>
      <origin rpy="0.00000 0.00000 0.00000" xyz="0.00006 -0.00002 0.06622"/>
      <mass value="0.30000"/>
    </inertial>
    <visual name="right_wheel_1_visual">
      <origin rpy="-3.14159 -0.00000 0.00000" xyz="-0.00000 -0.00000 -0.00000"/>
      <material name="Rubber"/>
      <geometry>
        <mesh filename="package://bodenbot/description/meshes/dae/wheel_right.dae" scale="1.00000 1.00000 1.00000"/>
      </geometry>
    </visual>
  </link>
  <link name="right_wheel_2_link">
    <collision name="right_wheel_2_collision">
      <origin rpy="3.14159 0.00000 0.00000" xyz="0.00006 -0.00002 0.06622"/>
      <geometry>
        <cylinder radius="0.13329" length="0.10744"/>
      </geometry>
    </collision>
    <inertial>
      <inertia ixx="0.00162" ixy="0.00000" ixz="0.00000" iyy="0.00267" iyz="0.00000" izz="0.00162"/>
      <origin rpy="0.00000 0.00000 0.00000" xyz="0.00006 -0.00002 0.06622"/>
      <mass value="0.30000"/>
    </inertial>
    <visual name="right_wheel_2_visual">
      <origin rpy="3.14159 0.00000 0.00000" xyz="0.00000 0.00000 -0.00000"/>
      <material name="Rubber"/>
      <geometry>
        <mesh filename="package://bodenbot/description/meshes/dae/wheel_right.dae" scale="1.00000 1.00000 1.00000"/>
      </geometry>
    </visual>
  </link>
  <link name="right_wheel_3_link">
    <collision name="right_wheel_3_collision">
      <origin rpy="-3.14159 -0.00000 0.00000" xyz="0.00001 -0.00000 0.06622"/>
      <geometry>
        <cylinder radius="0.13335" length="0.10744"/>
      </geometry>
    </collision>
    <inertial>
      <inertia ixx="0.00162" ixy="0.00000" ixz="0.00000" iyy="0.00267" iyz="0.00000" izz="0.00162"/>
      <origin rpy="0.00000 0.00000 0.00000" xyz="0.00001 -0.00000 0.06622"/>
      <mass value="0.30000"/>
    </inertial>
    <visual name="right_wheel_3_visual">
      <origin rpy="-3.14159 -0.00000 0.00000" xyz="0.00000 0.00000 0.00000"/>
      <material name="Rubber"/>
      <geometry>
        <mesh filename="package://bodenbot/description/meshes/dae/wheel_right.dae" scale="1.00000 1.00000 1.00000"/>
      </geometry>
    </visual>
  </link>
  <link name="sensor_package_link">
    <inertial>
      <inertia ixx="0.00129" ixy="0.00000" ixz="0.00001" iyy="0.00052" iyz="0.00001" izz="0.00154"/>
      <origin rpy="0.00000 0.00000 0.00000" xyz="0.00247 0.00036 0.01919"/>
      <mass value="0.30000"/>
    </inertial>
    <visual name="sensor_package_visual">
      <origin rpy="-1.57080 0.00000 0.00000" xyz="0.00000 0.00000 0.00000"/>
      <material name="Plastic"/>
      <geometry>
        <mesh filename="package://bodenbot/description/meshes/dae/sensor_package.dae" scale="1.00000 1.00000 1.00000"/>
      </geometry>
    </visual>
  </link>
  <link name="suspension_left_main_link">
    <inertial>
      <inertia ixx="0.03839" ixy="-0.00521" ixz="-0.05264" iyy="0.11630" iyz="-0.00362" izz="0.07964"/>
      <origin rpy="0.00000 0.00000 0.00000" xyz="-0.14394 -0.11660 0.07202"/>
      <mass value="2.00000"/>
    </inertial>
    <visual name="suspension_left_main_visual">
      <origin rpy="3.14159 0.00000 0.00000" xyz="0.00000 0.00000 0.00000"/>
      <material name="Rubber"/>
      <geometry>
        <mesh filename="package://bodenbot/description/meshes/dae/suspension_left.dae" scale="1.00000 1.00000 1.00000"/>
      </geometry>
    </visual>
  </link>
  <link name="suspension_left_sub_link">
    <inertial>
      <inertia ixx="0.01321" ixy="0.00058" ixz="-0.00162" iyy="0.04851" iyz="-0.00201" izz="0.03744"/>
      <origin rpy="0.00000 0.00000 0.00000" xyz="0.01868 -0.09125 0.01201"/>
      <mass value="2.50000"/>
    </inertial>
    <visual name="suspension_left_sub_visual">
      <origin rpy="3.14159 0.00000 -0.00000" xyz="-0.00000 -0.00000 0.00000"/>
      <material name="Rubber"/>
      <geometry>
        <mesh filename="package://bodenbot/description/meshes/dae/suspension_left_sub.dae" scale="1.00000 1.00000 1.00000"/>
      </geometry>
    </visual>
  </link>
  <link name="suspension_right_main_link">
    <inertial>
      <inertia ixx="0.03839" ixy="0.00521" ixz="-0.05264" iyy="0.11630" iyz="0.00362" izz="0.07964"/>
      <origin rpy="0.00000 0.00000 0.00000" xyz="0.14394 -0.11660 0.07202"/>
      <mass value="2.00000"/>
    </inertial>
    <visual name="suspension_right_main_visual">
      <origin rpy="0.00000 0.00000 -0.00000" xyz="0.00000 0.00000 0.00000"/>
      <material name="Rubber"/>
      <geometry>
        <mesh filename="package://bodenbot/description/meshes/dae/suspension_right.dae" scale="1.00000 1.00000 1.00000"/>
      </geometry>
    </visual>
  </link>
  <link name="suspension_right_sub_link">
    <inertial>
      <inertia ixx="0.01321" ixy="-0.00058" ixz="-0.00162" iyy="0.04851" iyz="0.00201" izz="0.03744"/>
      <origin rpy="0.00000 0.00000 0.00000" xyz="-0.01868 -0.09125 0.01201"/>
      <mass value="2.50000"/>
    </inertial>
    <visual name="suspension_right_sub_visual">
      <origin rpy="-0.00000 0.00000 0.00000" xyz="0.00000 0.00000 -0.00000"/>
      <material name="Metal"/>
      <geometry>
        <mesh filename="package://bodenbot/description/meshes/dae/suspension_right_sub.dae" scale="1.00000 1.00000 1.00000"/>
      </geometry>
    </visual>
  </link>
</xacro:macro>
</robot>
